Workbook
Name AbraSG: 'inventory 5-6'!$B$63:$B$110
Name AbraSG: 'Inventory of Positions'!$B$63:$B$109
Name age: 'staffing plan'!$BA$12:$BA$241
Name agegroup: 'staffing plan'!$BB$12:$BB$242
Name ApayaoSG: 'inventory 5-6'!$B$113:$B$135
Name ApayaoSG: 'Inventory of Positions'!$B$112:$B$133
Name BaguioSG: 'inventory 5-6'!$B$138:$B$144
Name BaguioSG: 'Inventory of Positions'!$B$136:$B$142
Name BARNACHEA: '[1]salary grade'!$B$2:$I$29
Name barnachea: 'salary grade'!$B$2:$I$29
Name BARNACHEA1: 'salary grade'!$M$2:$T$29
Name barnachea18: #REF!
Name barnachea18: #REF!
Name barnachea18: #REF!
Name barnachea18: #REF!
Name barnachea18: #REF!
Name BenguetSG: 'inventory 5-6'!$B$147:$B$176
Name BenguetSG: 'Inventory of Positions'!$B$145:$B$173
Name gender: 'staffing plan'!$AY$12:$AY$241
Name genderagegroupstation: 'staffing plan'!$BD$12:$BD$242
Name GENDERSTATION: 'staffing plan'!$L$12:$L$241
Name GRACE: '[1]salary grade'!$B$1:$I$1
Name grace: 'salary grade'!$B$1:$I$1
Name gRACE1: 'salary grade'!$M$1:$T$1
Name IDICA: '[1]salary grade'!$A$2:$I$29
Name idica: 'salary grade'!$A$2:$I$29
Name IDICA1: 'salary grade'!$L$2:$S$29
Name idica18: #REF!
Name idica18: #REF!
Name idica18: #REF!
Name idica18: #REF!
Name idica18: #REF!
Name IfugaoSG: 'inventory 5-6'!$B$179:$B$203
Name IfugaoSG: 'Inventory of Positions'!$B$176:$B$200
Name KalingaSG: 'inventory 5-6'!$B$206:$B$228
Name KalingaSG: 'Inventory of Positions'!$B$203:$B$225
Name Level: 'staffing plan'!$AM$12:$AM$240
Name leveljo: 'COS in CO'!#REF!
Name leveljo: #REF!
Name leveljo: 'JO inventory'!$J$9:$J$64
Name leveljo18: '[2]JO inventory'!$J$9:$J$66
Name MtProvinceSG: 'inventory 5-6'!$B$231:$B$254
Name MtProvinceSG: 'Inventory of Positions'!$B$228:$B$251
Name nORMAN: '[1]salary grade'!$A$2:$A$29
Name norman: 'salary grade'!$A$2:$A$29
Name NORMAN1: 'salary grade'!$L$2:$L$29
Name Norman18: #REF!
Name Norman18: #REF!
Name Norman18: #REF!
Name Norman18: #REF!
Name Norman18: #REF!
Name positiontitle: 'staffing plan'!#REF!
Name PosStSex: 'staffing plan'!$K$12:$K$240
Name PTSexCat: 'staffing plan'!$BE$12:$BE$240
Name PTStation: 'staffing plan'!$J$12:$J$240
Name sexjo: 'COS in CO'!#REF!
Name sexjo: #REF!
Name sexjo: 'JO inventory'!$G$9:$G$64
Name sexjo18: '[2]JO inventory'!$G$9:$G$66
Name sexlevel: 'JO inventory'!#REF!

Sheet RatPlan Strat
A1: PLANTILLA OF PERSONNEL
A2: as of August 5, 2010
A3: LIST OF VACANT POSITIONS
A5: DEPARTMENT: Department of the Interior and Local Government, CORDILLERA ADMINISTRATIVE REGION
A6: ITEM NUMBER | B6: Plantilla location (1998) | C6: POSITION TITLE | D6: S G | E6: A N N U A L S A L A R Y | H6: STEP | I6: A R E A | L6: P/P/A/ ATTRI-BUTION | U6: I N C U M B E N T | V6: GENDER | W6: DATE OF BIRTH | Y6: Tax Identification Number (TIN) | AA6: DATE OF ORIGINAL APPT | AB6: DATE OF LAST PROMO-TION | AC6: STATUS | AD6: ELIGIBILITY | AE6: REMARK | AM6: ITEM NUMBER | AN6: NEW POSITION TITLE | AO6: S G | AP6: STEP | AR6: I N C U M B E N T
A7: E X I S T I N G | AL7: DBM ACTION | AM7: A P P R O V E D | AT7: OPTION | AU7: QUALIFICATION STANDARDS | AY7: PERSONNEL ACTION
A8: ITEM NUMBER | B8: Plantilla location (1998) | C8: POSITION TITLE | D8: S G | E8: A U T H O - R I Z E D | F8: A C T U A L | G8: a c t u a l (dec 31, '07) | H8: STEP | I8: CODE | J8: TYPE | K8: LEVEL | L8: P/P/A/ ATTRI-BUTION | M8: Present Station of Incumbent | T8: Monthly Salary (6/29/10) | U8: I N C U M B E N T | X8: age | Z8: date of tranfer to DILG | AM8: POSITION TITLE | AN8: NEW POSITION TITLE | AO8: S G | AP8: STEP | AQ8: Monthly Salary (6/29/10) | AR8: I N C U M B E N T | AS8: I N C U M B E N T | AU8: EDUCATION | AV8: EXPERIENCE | AW8: TRAINING | AX8: ELIGIBILITY
A9: 1 | C9: 2 | E9: 3 | F9: 4 | H9: 5 | I9: 6 | J9: 7 | K9: 8 | L9: 9 | U9: 10 | V9: 11 | W9: 12 | Y9: 13 | AA9: 14 | AB9: 15 | AC9: 16 | AD9: 17 | AH9: 2ND TRANCHE | AP9: 5 | AR9: 10
A10: Office of the Regional Director | B10: . | AF10: authorized | AG10: previous | AH10: new | AI10: as dec 31 | AJ10: difference | AL10: Office of the Regional Director
A11: OSEC-DILGB-DIR 4-18-1998 | B11: Regional Office | C11: Director IV | D11: 28 | E11: =AF11*12 -> 582948 | F11: =+AH11*12 -> 610092 | G11: 346262 | H11: 4 | I11: 011 | J11: R | K11: K | L11: A.03.a.01.c | M11: Regional Office | N11: ONUS | O11: Patrick | P11: =UPPER(O11) -> PATRICK | R11: D | S11: =P11&" "&R11&"."&" "&N11&" "&Q11 -> PATRICK D. ONUS | T11: 50841 | U11: ONUS, Patrick Damoking | V11: M | W11: 16644 | X11: =(NOW()-W11) -> 29461.538 | Y11: 127-933-059 | AA11: 25345 | AB11: 39398 | AC11: P | AD11: CESO IV | AF11: 48579 | AG11: 41291 | AH11: 50841 | AJ11: =AH11-AG11 -> 9550 | AL11: Retained | AM11: OSEC-DILGB-DIR 4-18-1998 | AN11: Director IV | AO11: 28 | AP11: 4 | AQ11: 50841 | AR11: ONUS, Patrick Damoking | AS11: =IF(AR11="(Vacant)",AR11,IF(AR11="",AR11,"With Incumbent")) -> With Incumbent
A12: OSEC-DILGB-DIR 3-4-1998 | B12: Regional Office | C12: Director III | D12: 27 | E12: =AF12*12 -> 546060 | F12: =+AH12*12 -> 608088 | G12: =29878*12 -> 358536 | H12: 8 | I12: 011 | J12: R | K12: K | L12: A.03.a.01.c | M12: Regional Office | N12: MANGANGEY | O12: Robert | P12: =UPPER(O12) -> ROBERT | Q12: Sr. | R12: L | S12: =P12&" "&R12&"."&" "&N12&" "&Q12 -> ROBERT L. MANGANGEY Sr. | T12: =608088/12 -> 50674 | U12: MANGANGEY, Robert Sr. Loyosen | V12: M | W12: 16870 | X12: =(NOW()-W12) -> 29235.538 | Y12: 127-934-019 | Z12: 27204 | AA12: 27204 | AB12: 39979 | AC12: P | AD12: CESO IV | AF12: 45505 | AG12: =506172/12 -> 42181 | AH12: =608088/12 -> 50674 | AJ12: =AH12-AG12 -> 8493 | AL12: Retained | AM12: OSEC-DILGB-DIR 3-4-1998 | AN12: Director III | AO12: 27 | AP12: 8 | AQ12: =608088/12 -> 50674 | AR12: MANGANGEY, Robert Sr. Loyosen | AS12: =IF(AR12="(Vacant)",AR12,IF(AR12="",AR12,"With Incumbent")) -> With Incumbent
A13: OSEC-DILGB-ATTY 4-9-1998 | B13: Regional Office | C13: Attorney IV | D13: 23 | E13: =AF13*12 -> 421728 | F13: =+AH13*12 -> 442140 | G13: 277668 | H13: 4 | I13: 011 | J13: R | K13: S | L13: A.03.a.01.c | M13: Regional Office | N13: KIWANG | O13: Tomas | P13: =UPPER(O13) -> TOMAS | Q13: Jr. | R13: A | S13: =P13&" "&R13&"."&" "&N13&" "&Q13 -> TOMAS A. KIWANG Jr. | T13: 36845 | U13: KIWANG, Tomas Jr. Amindalan | V13: M | W13: 26444 | X13: =(NOW()-W13) -> 19661.538 | Y13: 166-271-358 | Z13: 35916 | AA13: 35262 | AB13: 37039 | AC13: P | AD13: RA 1080 | AF13: 35144 | AG13: 31467 | AH13: 36845 | AJ13: =AH13-AG13 -> 5378 | AL13: Retained | AM13: OSEC-DILGB-ATTY 4-9-1998 | AN13: Attorney IV | AO13: 23 | AP13: 4 | AQ13: 36845 | AR13: KIWANG, Tomas Jr. Amindalan | AS13: =IF(AR13="(Vacant)",AR13,IF(AR13="",AR13,"With Incumbent")) -> With Incumbent
AL14: New Position | AM14: New | AN14: Planning Officer III | AO14: 18 | AP14: 1 | AQ14: 25259 | AR14: (Vacant) | AS14: =IF(AR14="(Vacant)",AR14,IF(AR14="",AR14,"With Incumbent")) -> (Vacant) | AU14: Bachelor' Degree Relevant ot the Job | AV14: 2 years of Relevant Experience | AW14: 8 Hours of Relevant Training | AX14: CSP / Second Level Eligibility | AY14: FOR ASSESSMENT
AL15: New Position | AM15: New | AN15: Information Technology Officer I | AO15: 19 | AP15: 1 | AQ15: 27088 | AR15: (Vacant) | AS15: =IF(AR15="(Vacant)",AR15,IF(AR15="",AR15,"With Incumbent")) -> (Vacant) | AU15: Bachelor' Degree Relevant ot the Job | AV15: 2 years of Relevant Experience | AW15: 8 Hours of Relevant Training | AX15: CSP / Second Level Eligibility | AY15: FOR ASSESSMENT
A16: OSEC-DILGB-ADOF4-69-2005 | B16: Regional Office | C16: Administrative Officer IV (Information Officer II) | D16: 15 | E16: =AF16*12 -> 245880 | F16: =+AH16*12 -> 254064 | G16: 179940 | H16: 3 | I16: 011 | J16: R | K16: A | L16: A.03.a.01.c | M16: Regional Office | N16: RIMANDO | O16: Marie Cris | P16: =UPPER(O16) -> MARIE CRIS | R16: L | S16: =P16&" "&R16&"."&" "&N16&" "&Q16 -> MARIE CRIS L. RIMANDO | T16: 21172 | U16: RIMANDO, Marie Cris Lim | V16: F | W16: 24278 | X16: =(NOW()-W16) -> 21827.538 | Y16: 129-983-169 | AA16: 36374 | AB16: 37809 | AC16: P | AD16: CSP | AF16: 20490 | AG16: 19040 | AH16: 21172 | AJ16: =AH16-AG16 -> 2132 | AL16: To FAD (1)
A17: OSEC-DILGB-COMPRO2-9-1998 | B17: Regional Office | C17: Computer Programmer II | D17: 15 | E17: =AF17*12 -> 245880 | F17: =+AH17*12 -> 254064 | G17: 179940 | H17: 3 | I17: 011 | J17: R | K17: S | L17: A.03.a.01.c | M17: Regional Office | N17: WALANG | O17: Marlon | P17: =UPPER(O17) -> MARLON | R17: S | S17: =P17&" "&R17&"."&" "&N17&" "&Q17 -> MARLON S. WALANG | T17: 21172 | U17: WALANG, Marlon Silvada | V17: M | W17: 27738 | X17: =(NOW()-W17) -> 18367.538 | Y17: 190-830-006 | AA17: 36461 | AB17: 37355 | AC17: P | AD17: RA 1080 | AF17: 20490 | AG17: 19040 | AH17: 21172 | AJ17: =AH17-AG17 -> 2132 | AL17: To MED/Reclass (2)
A18: OSEC-DILGB-ADAS3-64-2005 | B18: Regional Office | C18: Administrative Assistant III (Secretary II) | D18: 9 | E18: =AF18*12 -> 163956 | F18: =+AH18*12 -> 172080 | G18: 132468 | H18: 4 | I18: 011 | J18: R | K18: A | L18: A.03.a.01.c | M18: Regional Office | N18: DAOAS | O18: Marian | P18: =UPPER(O18) -> MARIAN | R18: B | S18: =P18&" "&R18&"."&" "&N18&" "&Q18 -> MARIAN B. DAOAS | T18: 14340 | U18: DAOAS, Marian Bigsang | V18: F | W18: 23697 | X18: =(NOW()-W18) -> 22408.538 | Y18: 185-738-006 | AA18: 35037 | AB18: 36069 | AC18: P | AD18: CSP | AF18: 13663 | AG18: 13242 | AH18: 14340 | AJ18: =AH18-AG18 -> 1098 | AL18: Retained | AM18: OSEC-DILGB-ADAS3-64-2005 | AN18: Administrative Assistant III (Secretary II) | AO18: 9 | AP18: 4 | AQ18: 14340 | AR18: DAOAS, Marian Bigsang | AS18: =IF(AR18="(Vacant)",AR18,IF(AR18="",AR18,"With Incumbent")) -> With Incumbent
A19: OSEC-DILGB-ADA6-92-2005 | B19: Regional Office | C19: Administrative Aide VI (CEO II) | D19: 6 | E19: =AF19*12 -> 132744 | F19: =+AH19*12 -> 148764 | G19: 116436 | H19: 8 | I19: 011 | J19: R | K19: A | L19: A.03.a.01.c | M19: Regional Office | N19: GONZALES | O19: Marlene | P19: =UPPER(O19) -> MARLENE | R19: C | S19: =P19&" "&R19&"."&" "&N19&" "&Q19 -> MARLENE C. GONZALES | T19: 12397 | U19: GONZALES, Marlene Castro | V19: F | W19: 25348 | X19: =(NOW()-W19) -> 20757.538 | Y19: 127-933-034 | AA19: 32672 | AB19: 32672 | AC19: P | AD19: RES 435 | AF19: 11062 | AG19: 11669 | AH19: 12397 | AJ19: =AH19-AG19 -> 728 | AL19: Abolished | AT19: Remain in the Service | AY19: to ADA6-95 PO
A20: OSEC-DILGB-ADA6-93-2005 | B20: Regional Office | C20: Administrative Aide VI (Steno II) | D20: 6 | E20: =AF20*12 -> 132744 | F20: =+AH20*12 -> 132744 | G20: vacant | H20: 1 | I20: 011 | J20: R | K20: A | L20: A.03.a.01.c | P20: =UPPER(O20) | S20: =P20&" "&R20&"."&" "&N20&" "&Q20 -> . | T20: 11062 | U20: (Vacant) | AF20: 11062 | AG20: 10133 | AH20: 11062 | AJ20: =AH20-AG20 -> 929 | AL20: Abolished
A21: OSEC-DILGB-ADA4-83-2005 | B21: Regional Office | C21: Administrative Aide IV (Driver II) | D21: 4 | E21: =AF21*12 -> 114432 | F21: =+AH21*12 -> 120096 | G21: 90432 | H21: 4 | I21: 011 | J21: R | K21: A | L21: A.03.a.01.c | M21: Regional Office | N21: TICBAEN | O21: Mark Anthony | P21: =UPPER(O21) -> MARK ANTHONY | R21: D | S21: =P21&" "&R21&"."&" "&N21&" "&Q21 -> MARK ANTHONY D. TICBAEN | T21: 10008 | U21: TICBAEN, Mark Anthony Duquil | V21: M | W21: 27822 | X21: =(NOW()-W21) -> 18283.538 | Y21: 914-805-353 | AA21: 36168 | AB21: 36168 | AC21: P | AD21: MC 11 | AF21: 9536 | AG21: 9252 | AH21: 10008 | AJ21: =AH21-AG21 -> 756 | AL21: Retained | AM21: OSEC-DILGB-ADA4-83-2005 | AN21: Administrative Aide IV (Driver II) | AO21: 4 | AP21: 4 | AQ21: 10008 | AR21: TICBAEN, Mark Anthony Duquil | AS21: =IF(AR21="(Vacant)",AR21,IF(AR21="",AR21,"With Incumbent")) -> With Incumbent
A22: OSEC-DILGB-ADA3-61-2005 | B22: Regional Office | C22: Administrative Aide III (Driver I) | D22: 3 | E22: =AF22*12 -> 106248 | F22: =+AH22*12 -> 111504 | G22: 85836 | H22: 4 | I22: 011 | J22: R | K22: A | L22: A.03.a.01.c | M22: Regional Office | N22: TAMONDONG | O22: Jonathan | P22: =UPPER(O22) -> JONATHAN | R22: A | S22: =P22&" "&R22&"."&" "&N22&" "&Q22 -> JONATHAN A. TAMONDONG | T22: 9292 | U22: TAMONDONG, Jonathan Ambat | V22: M | W22: 24419 | X22: =(NOW()-W22) -> 21686.538 | Y22: 175-568-367 | AA22: 34808 | AB22: 36054 | AC22: P | AD22: MC 11 | AF22: 8854 | AG22: 8580 | AH22: 9292 | AJ22: =AH22-AG22 -> 712 | AL22: To FAD / Retained(3)
A23: Sub-Total | D23: =COUNTIF(D11:D22,">.01") -> 10 | AM23: Sub-Total | AO23: =COUNTIF(AO11:AO22,">.01") -> 7 | AR23: =COUNTIF(AR11:AR22,">.01") -> 0
A24: 62,000000000 Technical Services Division | AL24: Capability Development Division
A25: OSEC-DILGB-LGOO7-37-1998 | B25: Regional Office | C25: Local Government Operations Officer VII | D25: 24 | E25: =AF25*12 -> 449676 | F25: =+AH25*12 -> 449676 | G25: 274860 | H25: 1 | I25: 011 | J25: P | K25: K | L25: A.03.a.01.c | M25: Regional Office | N25: DUMELOD | O25: Rosario | P25: =UPPER(O25) -> ROSARIO | R25: B | S25: =P25&" "&R25&"."&" "&N25&" "&Q25 -> ROSARIO B. DUMELOD | T25: 37473 | U25: DUMELOD, Rosario BUMINAANG | V25: F | W25: 23285 | X25: =(NOW()-W25) -> 22820.538 | Y25: 127-934-454 | AA25: 32687 | AB25: 40261 | AC25: P | AD25: CSP | AF25: 37473 | AG25: 31334 | AH25: 37473 | AJ25: =AH25-AG25 -> 6139 | AL25: Retained | AM25: OSEC-DILGB-LGOO7-37-1998 | AN25: Local Government Operations Officer VII | AO25: 24 | AP25: 1 | AQ25: 37473 | AR25: DUMELOD, Rosario BUMINAANG | AS25: =IF(AR25="(Vacant)",AR25,IF(AR25="",AR25,"With Incumbent")) -> With Incumbent
A26: OSEC-DILGB-LGOO6-12-1998 | B26: Regional Office | C26: Local Government Operations Officer VI | D26: 22 | E26: =AF26*12 -> 395676 | F26: =+AH26*12 -> 395676 | G26: vacant | H26: 1 | I26: 011 | J26: R | K26: T | L26: A.03.a.01.c | M26: Regional Office | N26: CLAUDIO | O26: Ofelia | P26: =UPPER(O26) -> OFELIA | R26: O | S26: =P26&" "&R26&"."&" "&N26&" "&Q26 -> OFELIA O. CLAUDIO | T26: 32973 | U26: CLAUDIO, Ofelia Linggon | V26: F | W26: 21997 | X26: =(NOW()-W26) -> 24108.538 | Y26: 127-934-210 | AA26: 32687 | AB26: 39510 | AC26: P | AD26: CSP | AF26: 32973 | AG26: 28134 | AH26: 32973 | AJ26: =AH26-AG26 -> 4839 | AL26: Retained | AM26: OSEC-DILGB-LGOO6-12-1998 | AN26: Local Government Operations Officer VI | AO26: 22 | AP26: 1 | AQ26: 32973 | AR26: CLAUDIO, Ofelia Linggon | AS26: =IF(AR26="(Vacant)",AR26,IF(AR26="",AR26,"With Incumbent")) -> With Incumbent
A27: OSEC-DILGB-LGOO5-791-1998 | B27: Regional Office | C27: Local Government Operations Officer V | D27: 20 | E27: =AF27*12 -> 348624 | F27: =+AH27*12 -> 360012 | G27: 240816 | H27: 3 | I27: 0540 | J27: M | K27: T | L27: A.03.a.01.c | M27: Benguet | N27: BALLUG | O27: Rene Vincent | P27: =UPPER(O27) -> RENE VINCENT | R27: I | S27: =P27&" "&R27&"."&" "&N27&" "&Q27 -> RENE VINCENT I. BALLUG | T27: 30001 | U27: BALLUG, Rene Vincent Ilacad | V27: M | W27: 25501 | X27: =(NOW()-W27) -> 20604.538 | Y27: 185-969-809 | AA27: 35487 | AB27: 37561 | AC27: P | AD27: CSP | AF27: 29052 | AG27: 26314 | AH27: 30001 | AJ27: =AH27-AG27 -> 3687 | AL27: Retained | AM27: OSEC-DILGB-LGOO5-791-1998 | AN27: Local Government Operations Officer V | AO27: 20 | AP27: 3 | AQ27: 30001 | AR27: BALLUG, Rene Vincent Ilacad | AS27: =IF(AR27="(Vacant)",AR27,IF(AR27="",AR27,"With Incumbent")) -> With Incumbent
A28: OSEC-DILGB-LGOO5-802-1998 | B28: Regional Office | C28: Local Government Operations Officer V | D28: 20 | E28: =AF28*12 -> 348624 | F28: =+AH28*12 -> 354264 | G28: 240816 | H28: 2 | I28: 011 | J28: R | K28: T | L28: A.03.a.01.c | M28: Ifugao | N28: CORTEZ | O28: Melchor Anthony | P28: =UPPER(O28) -> MELCHOR ANTHONY | R28: G | S28: =P28&" "&R28&"."&" "&N28&" "&Q28 -> MELCHOR ANTHONY G. CORTEZ | T28: 29522 | U28: CORTEZ, Melchor Anthony Guimbatan | V28: M | W28: 25574 | X28: =(NOW()-W28) -> 20531.538 | Y28: 173-594-522 | AA28: 35100 | AB28: 38322 | AC28: P | AD28: CSP | AF28: 29052 | AG28: 25799 | AH28: 29522 | AJ28: =AH28-AG28 -> 3723 | AL28: Retained | AM28: OSEC-DILGB-LGOO5-802-1998 | AN28: Local Government Operations Officer V | AO28: 20 | AP28: 2 | AQ28: 29522 | AR28: CORTEZ, Melchor Anthony Guimbatan | AS28: =IF(AR28="(Vacant)",AR28,IF(AR28="",AR28,"With Incumbent")) -> With Incumbent
A29: OSEC-DILGB-LGOO5-813-1998 | B29: Regional Office | C29: Local Government Operations Officer V | D29: 20 | E29: =AF29*12 -> 348624 | F29: =+AH29*12 -> 348624 | G29: vacant | H29: 1 | I29: 011 | J29: R | K29: T | L29: A.03.a.01.c | M29: Apayao | N29: CENU | O29: Merina | P29: =UPPER(O29) -> MERINA | R29: B | S29: =P29&" "&R29&"."&" "&N29&" "&Q29 -> MERINA B. CENU | T29: 29052 | U29: CENU. Merina Bagasol | V29: F | W29: 28132 | X29: =(NOW()-W29) -> 17973.538 | Y29: 905-486-436 | AA29: 36299 | AB29: 39510 | AC29: P | AD29: CSP | AF29: 29052 | AG29: 25295 | AH29: 29052 | AJ29: =AH29-AG29 -> 3757 | AL29: Retained | AM29: OSEC-DILGB-LGOO5-813-1998 | AN29: Local Government Operations Officer V | AO29: 20 | AP29: 1 | AQ29: 29052 | AR29: CENU. Merina Bagasol | AS29: =IF(AR29="(Vacant)",AR29,IF(AR29="",AR29,"With Incumbent")) -> With Incumbent
A30: OSEC-DILGB-LGOO4-160-1998 | B30: Regional Office | C30: Local Government Operations Officer IV | D30: 18 | E30: =AF30*12 -> 303108 | F30: =+AH30*12 -> 313092 | G30: 219684 | H30: 3 | I30: 0537 | J30: M | K30: T | L30: A.03.a.01.c | M30: Baguio City | N30: MALIG | O30: Julie | P30: =UPPER(O30) -> JULIE | R30: C | S30: =P30&" "&R30&"."&" "&N30&" "&Q30 -> JULIE C. MALIG | T30: 26091 | U30: MALIG, Julie Capiato | V30: F | W30: 25394 | X30: =(NOW()-W30) -> 20711.538 | Y30: 154-221-422 | AA30: 35107 | AB30: 37235 | AC30: P | AD30: CSP | AF30: 25259 | AG30: 23115 | AH30: 26091 | AJ30: =AH30-AG30 -> 2976 | AL30: To PO/Reclass
A31: OSEC-DILGB-LGOO4-161-1998 | B31: Regional Office | C31: Local Government Operations Officer IV | D31: 18 | E31: =AF31*12 -> 303108 | F31: =+AH31*12 -> 303108 | G31: vacant | H31: 1 | I31: 06 | J31: R | K31: A | L31: A.03.a.01.c | M31: Regional Office | N31: CAWIS | O31: Odemar | P31: =UPPER(O31) -> ODEMAR | R31: M | S31: =P31&" "&R31&"."&" "&N31&" "&Q31 -> ODEMAR M. CAWIS | T31: 25259 | U31: CAWIS, Odemar Mendoza | V31: M | W31: 25761 | X31: =(NOW()-W31) -> 20344.538 | Y31: 144-070234 | AA31: 36434 | AB31: 40262 | AC31: P | AD31: CSP | AF31: 25259 | AG31: 22214 | AH31: 25259 | AJ31: =AH31-AG31 -> 3045 | AL31: Retained | AM31: OSEC-DILGB-LGOO4-161-1998 | AN31: Local Government Operations Officer IV | AO31: 18 | AP31: 1 | AQ31: 25259 | AR31: CAWIS, Odemar Mendoza | AS31: =IF(AR31="(Vacant)",AR31,IF(AR31="",AR31,"With Incumbent")) -> With Incumbent
A32: OSEC-DILGB-LGOO4-162-1998 | B32: Regional Office | C32: Local Government Operations Officer IV | D32: 18 | E32: =AF32*12 -> 303108 | F32: =+AH32*12 -> 303108 | G32: 214332 | H32: 1 | I32: 011 | J32: R | K32: A | L32: A.03.a.01.c | S32: Vacant PALENG, Mory D. | T32: 25259 | U32: (Vacant) | AF32: 25259 | AG32: 22214 | AH32: 25259 | AJ32: =AH32-AG32 -> 3045 | AL32: To PO/Reclass
A33: OSEC-DILGB-LGOO4-164-1998 | B33: Regional Office | C33: Local Government Operations Officer IV | D33: 18 | E33: =AF33*12 -> 303108 | F33: =+AH33*12 -> 303108 | G33: 214332 | H33: 1 | I33: 011 | J33: R | K33: A | L33: A.03.a.01.c | M33: Regional Office | N33: GARCIA | O33: Florinda | P33: =UPPER(O33) -> FLORINDA | R33: M | S33: =P33&" "&R33&"."&" "&N33&" "&Q33 -> FLORINDA M. GARCIA | T33: 25259 | U33: GARCIA, Florinda Manuyag | V33: F | W33: 22504 | X33: =(NOW()-W33) -> 23601.538 | Y33: 122-174-963 | AA33: 36100 | AB33: 40262 | AC33: P | AD33: CSP | AF33: 25259 | AG33: 22214 | AH33: 25259 | AJ33: =AH33-AG33 -> 3045 | AL33: Retained | AM33: OSEC-DILGB-LGOO4-164-1998 | AN33: Local Government Operations Officer IV | AO33: 18 | AP33: 1 | AQ33: 25259 | AR33: GARCIA, Florinda Manuyag | AS33: =IF(AR33="(Vacant)",AR33,IF(AR33="",AR33,"With Incumbent")) -> With Incumbent
A34: OSEC-DILGB-ADAS1-24-2005 | B34: Regional Office | C34: Administrative Assistant I (CO I) | D34: 7 | E34: =AF34*12 -> 130296 | F34: =+AH34*12 -> 142428 | G34: vacant | H34: 1 | I34: 011 | J34: R | K34: A | L34: A.03.a.01.c | P34: =UPPER(O34) | S34: =P34&" "&R34&"."&" "&N34&" "&Q34 -> . | T34: 11869 | U34: (Vacant) | AF34: 10858 | AG34: 10858 | AH34: 11869 | AJ34: =AH34-AG34 -> 1011 | AL34: Abolished
E35: =AF35*12 -> 132744 | F35: =+AH35*12 -> 137100 | G35: 102912 | I35: 011 | J35: R | K35: A | L35: A.03.a.01.c | M35: Kalinga | N35: MAGO | O35: Carmelita | P35: =UPPER(O35) -> CARMELITA | R35: C | S35: =P35&" "&R35&"."&" "&N35&" "&Q35 -> CARMELITA C. MAGO | V35: F | W35: 20401 | X35: =(NOW()-W35) -> 25704.538 | Y35: 127-934-872 | AA35: 30769 | AB35: 37288 | AC35: P | AD35: CSSP | AF35: 11062 | AG35: 10548 | AH35: 11425 | AJ35: =AH35-AG35 -> 877 | AL35: Retained Fr FAD 4 | AM35: OSEC-DILGB-ADA6-97-2005 | AN35: Administrative Aide VI (Clerk III) | AO35: 6 | AP35: 3 | AQ35: 11425 | AR35: MAGO, Carmelita Cenabre | AS35: =IF(AR35="(Vacant)",AR35,IF(AR35="",AR35,"With Incumbent")) -> With Incumbent
A36: Sub-Total | D36: =COUNTIF(D25:D35,">.01") -> 10 | AM36: Sub-Total | AO36: =COUNTIF(AO25:AO35,">.01") -> 8
A37: 63,000000000 Operations Division | AL37: Monitoring and Evaluation Division
A38: OSEC-DILGB-LGOO7-38-1998 | B38: Regional Office | C38: Local Government Operations Officer VII | D38: 24 | E38: =AF38*12 -> 449676 | F38: =+AH38*12 -> 449676 | G38: vacant | H38: 1 | I38: 08 | J38: P | K38: K | L38: A.03.a.01.c | M38: Regional Office | N38: MADARIAGA | O38: Benjamin | P38: =UPPER(O38) -> BENJAMIN | R38: A | S38: =P38&" "&R38&"."&" "&N38&" "&Q38 -> BENJAMIN A. MADARIAGA | T38: 37473 | U38: MADARIAGA, Benjamin Acio | V38: M | W38: 16816 | X38: =(NOW()-W38) -> 29289.538 | Y38: 135-562-718 | AA38: 25520 | AB38: 39525 | AC38: P | AD38: CDO | AF38: 37473 | AG38: 31334 | AH38: 37473 | AJ38: =AH38-AG38 -> 6139 | AL38: Retained | AM38: OSEC-DILGB-LGOO7-38-1998 | AN38: Local Government Operations Officer VII | AO38: 24 | AP38: 1 | AQ38: 37473 | AR38: MADARIAGA, Benjamin Acio | AS38: =IF(AR38="(Vacant)",AR38,IF(AR38="",AR38,"With Incumbent")) -> With Incumbent
A39: OSEC-DILGB-LGOO6-14-1998 | B39: Regional Office | C39: Local Government Operations Officer VI | D39: 22 | E39: =23294*12 -> 279528 | F39: =+AH39*12 -> 395676 | G39: 260460 | H39: 1 | I39: 011 | J39: R | K39: T | L39: A.03.a.01.c | M39: Regional Office | N39: ADNOL | O39: Bable | P39: =UPPER(O39) -> BABLE | R39: G | S39: =P39&" "&R39&"."&" "&N39&" "&Q39 -> BABLE G. ADNOL | T39: 32973 | U39: ADNOL, Bable Ged-ang | V39: F | W39: 25374 | X39: =(NOW()-W39) -> 20731.538 | Y39: 185-743-190 | AA39: 34808 | AB39: 40262 | AC39: P | AD39: CSP | AF39: 32973 | AG39: 28134 | AH39: 32973 | AJ39: =AH39-AG39 -> 4839 | AL39: Retained | AM39: OSEC-DILGB-LGOO6-14-1998 | AN39: Local Government Operations Officer VI | AO39: 22 | AP39: 1 | AQ39: 32973 | AR39: ADNOL, Bable Ged-ang | AS39: =IF(AR39="(Vacant)",AR39,IF(AR39="",AR39,"With Incumbent")) -> With Incumbent
A40: OSEC-DILGB-LGOO5-824-1998 | B40: Regional Office | C40: Local Government Operations Officer V | D40: 20 | E40: =21537*12 -> 258444 | F40: =+AH40*12 -> 348624 | G40: 253020 | H40: 1 | I40: 011 | J40: R | K40: T | L40: A.03.a.01.c | M40: Apayao | N40: ACERET | O40: Wilnelia | P40: =UPPER(O40) -> WILNELIA | R40: M | S40: =P40&" "&R40&"."&" "&N40&" "&Q40 -> WILNELIA M. ACERET | T40: 29052 | U40: ACERET, Wilnelia Martinez | V40: F | W40: 28103 | X40: =(NOW()-W40) -> 18002.538 | Y40: 905-491-788 | AA40: 36024 | AB40: 39874 | AC40: P | AD40: CSP | AF40: 29052 | AG40: 25295 | AH40: 29052 | AJ40: =AH40-AG40 -> 3757 | AL40: Retained | AM40: OSEC-DILGB-LGOO5-824-1998 | AN40: Local Government Operations Officer V | AO40: 20 | AP40: 1 | AQ40: 29052 | AR40: ACERET, Wilnelia Martinez | AS40: =IF(AR40="(Vacant)",AR40,IF(AR40="",AR40,"With Incumbent")) -> With Incumbent
A41: OSEC-DILGB-LGOO5-835-1998 | B41: Regional Office | C41: Local Government Operations Officer V | D41: 20 | E41: =AF41*12 -> 348624 | F41: =+AH41*12 -> 360012 | G41: 240816 | H41: 3 | I41: 011 | J41: R | K41: T | L41: A.03.a.01.c | M41: Apayao | N41: BALDERAMA | O41: Antonio | P41: =UPPER(O41) -> ANTONIO | R41: C | S41: =P41&" "&R41&"."&" "&N41&" "&Q41 -> ANTONIO C. BALDERAMA | T41: 30001 | U41: BALDERAMA, Antonio Carbonel | V41: M | W41: 17986 | X41: =(NOW()-W41) -> 28119.538 | Y41: 127-934-972 | Z41: 31371 | AA41: 25385 | AB41: 37987 | AC41: P | AD41: CSP | AF41: 29052 | AG41: 26314 | AH41: 30001 | AJ41: =AH41-AG41 -> 3687 | AL41: Retained | AM41: OSEC-DILGB-LGOO5-835-1998 | AN41: Local Government Operations Officer V | AO41: 20 | AP41: 3 | AQ41: 30001 | AR41: BALDERAMA, Antonio Carbonel | AS41: =IF(AR41="(Vacant)",AR41,IF(AR41="",AR41,"With Incumbent")) -> With Incumbent
...

Sheet Reclass18

Sheet JO inventory
A1: LIST OF JOB ORDER/CONTRACT OF SERVICE/MOA PERSONNEL
A2: =CONCATENATE("As of ",TEXT(NOW(),"mmmm dd, yyyy")) -> As of March 24, 2026
A4: DEPARTMENT OF THE INTERIOR AND LOCAL GOVERNMENT
A5: Cordillera Administrative Region
A7: NO. | B7: SURNAME | C7: FIRSTNAME | D7: MIDDLE INITIAL | E7: Date of Birth | F7: Age | G7: Sex | H7: Level of CS Eligibility | I7: Work Status | J7: Level | K7: Start date | L7: End date | M7: 2018 1st Sem renewal | N7: No. of Years as JO/COS/ MOA | O7: Station | P7: Nature of Work | Q7: Position Title | R7: Fund Source | S7: monthlu salary | T7: ID NUMBER
P8: Select | Q8: Specify
A9: 1 | B9: Allig | C9: Mike Collins | D9: O | E9: 32370 | F9: =DATEDIF(E9,TODAY(),"Y") -> 37 | G9: M | H9: None | I9: Contract of Service | J9: 1 | K9: 42601 | L9: 43465 | M9: y | N9: =CONCATENATE(DATEDIF(K9,L9,"Y"),"y ",DATEDIF(K9+(360*(DATEDIF(K9,L9,"Y"))),L9,"M"),"m ",DATEDIF(K9+(30.5*(DATEDIF(K9,L9,"M"))),L9,"D"),"d") -> 2y 4m 10d | O9: Ifugao | P9: Admin. Support Services | Q9: Driver | R9: Regular Funds | S9: 10833 | T9: JO028 | U9: 42735 | V9: =DATEDIF(U9,TODAY(),"Y") -> 9
A10: =A119+1 -> 3 | B10: Badcao | C10: Jacinto | D10: B | E10: 31040 | F10: =DATEDIF(E10,TODAY(),"Y") -> 41 | G10: M | H10: RA 1080 Civil Engineer | I10: Contract of Service | J10: 2 | K10: 42887 | L10: 43465 | M10: y | N10: =CONCATENATE(DATEDIF(K10,L10,"Y"),"y ",DATEDIF(K10+(360*(DATEDIF(K10,L10,"Y"))),L10,"M"),"m ",DATEDIF(K10+(30.5*(DATEDIF(K10,L10,"M"))),L10,"D"),"d") -> 1y 7m 29d | O10: Region | P10: Technical Services | Q10: Engineer III | R10: LFP | S10: 36409 | T10: JO044
A11: =A10+1 -> 4 | B11: Balatbat | C11: Jaime Jr. | D11: A | E11: 28656 | F11: =DATEDIF(E11,TODAY(),"Y") -> 47 | G11: M | H11: None | I11: Contract of Service | J11: 1 | K11: 42629 | L11: 43465 | M11: y | N11: =CONCATENATE(DATEDIF(K11,L11,"Y"),"y ",DATEDIF(K11+(360*(DATEDIF(K11,L11,"Y"))),L11,"M"),"m ",DATEDIF(K11+(30*(DATEDIF(K11,L11,"M"))),L11,"D"),"d") -> 2y 3m 26d | O11: Region | P11: Admin. Support Services | Q11: Driver | R11: Regular Funds | S11: 10833 | T11: JO030
A12: =A11+1 -> 5 | B12: Ballug | C12: Jan Michael | D12: DG | E12: 33047 | F12: =DATEDIF(E12,TODAY(),"Y") -> 35 | G12: M | H12: None | I12: Contract of Service | J12: 1 | K12: 42767 | L12: 43465 | M12: y | N12: =CONCATENATE(DATEDIF(K12,L12,"Y"),"y ",DATEDIF(K12+(360*(DATEDIF(K12,L12,"Y"))),L12,"M"),"m ",DATEDIF(K12+(30.5*(DATEDIF(K12,L12,"M"))),L12,"D"),"d") -> 1y 11m 27d | O12: Baguio | P12: Admin. Support Services | Q12: Driver | R12: Regular Funds | S12: 10833 | T12: JO037 | U12: 42735 | V12: =DATEDIF(U12,TODAY(),"Y") -> 9
A13: =A12+1 -> 6 | B13: Blosan | C13: Marlon | D13: E | E13: 33316 | F13: =DATEDIF(E13,TODAY(),"Y") -> 35 | G13: M | H13: RA 1080 Civil Engineer | I13: Contract of Service | J13: 2 | K13: 42905 | L13: 43465 | M13: y | N13: =CONCATENATE(DATEDIF(K13,L13,"Y"),"y ",DATEDIF(K13+(360*(DATEDIF(K13,L13,"Y"))),L13,"M"),"m ",DATEDIF(K13+(30.5*(DATEDIF(K13,L13,"M"))),L13,"D"),"d") -> 1y 6m 11d | O13: Abra | P13: Technical Services | Q13: Engineer II | R13: LFP | S13: 28417 | T13: JO048
A14: =A13+1 -> 7 | B14: Bolhayon | C14: Jake | D14: B | E14: 32952 | F14: =DATEDIF(E14,TODAY(),"Y") -> 36 | G14: M | H14: None | I14: Contract of Service | J14: 1 | K14: 42552 | L14: 43465 | M14: y | N14: =CONCATENATE(DATEDIF(K14,L14,"Y"),"y ",DATEDIF(K14+(360*(DATEDIF(K14,L14,"Y"))),L14,"M"),"m ",DATEDIF(K14+(30.5*(DATEDIF(K14,L14,"M"))),L14,"D"),"d") -> 2y 6m 29d | O14: Ifugao | P14: Janitorial Services | Q14: Utility/Janitor | R14: Regular Funds | S14: 9478 | T14: JO026 | V14: =sumif(DATEDIF(O9,TODAY(),"Y")>.99,concatenate((DATEDIF(O9,TODAY(),"Y")," yr")),(sumif(DATEDIF(O9,TODAY(),"Y")<.99,concatenate((DATEDIF(O9,TODAY(),"M")," mo")),((sumif(DATEDIF(O9,TODAY(),"M")<.99,concatenate((DATEDIF(O9,TODAY(),"D")," days")),((("no date")))
A15: =A14+1 -> 8 | B15: Bumatay | C15: Michelle | D15: E | E15: 32944 | F15: =DATEDIF(E15,TODAY(),"Y") -> 36 | G15: F | H15: RA 1080 Sanitary Engineer | I15: Contract of Service | J15: 2 | K15: 42307 | L15: 43465 | M15: y | N15: =CONCATENATE(DATEDIF(K15,L15,"Y"),"y ",DATEDIF(K15+(360*(DATEDIF(K15,L15,"Y"))),L15,"M"),"m ",DATEDIF(K15+(30.5*(DATEDIF(K15,L15,"M"))),L15,"D"),"d") -> #NUM! | O15: Apayao | P15: Technical Services | Q15: Engineer III | R15: LFP | S15: 36409 | T15: JO019
A16: =A15+1 -> 9 | B16: Bumosao | C16: Charles | D16: D | E16: 31374 | F16: =DATEDIF(E16,TODAY(),"Y") -> 40 | G16: M | H16: RA 1080 Civil Engineer | I16: Contract of Service | J16: 2 | K16: 42201 | L16: 43465 | M16: y | N16: =CONCATENATE(DATEDIF(K16,L16,"Y"),"y ",DATEDIF(K16+(360*(DATEDIF(K16,L16,"Y"))),L16,"M"),"m ",DATEDIF(K16+(30.5*(DATEDIF(K16,L16,"M"))),L16,"D"),"d") -> 3y 6m 14d | O16: Kalinga | P16: Technical Services | Q16: Engineer III | R16: LFP | S16: 36409 | T16: JO017
A17: =A16+1 -> 10 | B17: Castro | C17: Angeline | D17: B | E17: 27437 | F17: =DATEDIF(E17,TODAY(),"Y") -> 51 | G17: F | H17: LET CSP CSSP | I17: Contract of Service | J17: 2 | K17: 42982 | L17: 43465 | M17: y | N17: =CONCATENATE(DATEDIF(K17,L17,"Y"),"y ",DATEDIF(K17+(360*(DATEDIF(K17,L17,"Y"))),L17,"M"),"m ",DATEDIF(K17+(30.5*(DATEDIF(K17,L17,"M"))),L17,"D"),"d") -> 1y 4m 26d | O17: Region | P17: Technical Services | Q17: Development Management Officer V | R17: CMGP/Kalsada | S17: 56610 | T17: JO051
A18: =A17+1 -> 11 | B18: Colintas | C18: Aris | D18: A | E18: 31099 | F18: =DATEDIF(E18,TODAY(),"Y") -> 41 | G18: M | H18: None | I18: Contract of Service | J18: 2 | K18: 42278 | L18: 43465 | M18: y | N18: =CONCATENATE(DATEDIF(K18,L18,"Y"),"y ",DATEDIF(K18+(360*(DATEDIF(K18,L18,"Y"))),L18,"M"),"m ",DATEDIF(K18+(30.5*(DATEDIF(K18,L18,"M"))),L18,"D"),"d") -> 3y 3m 28d | O18: Region | P18: IT Services | Q18: ISA I | R18: LFP | S18: 36409 | T18: JO018
A19: =A18+1 -> 12 | B19: Culti | C19: Avery | D19: B | E19: 27605 | F19: =DATEDIF(E19,TODAY(),"Y") -> 50 | G19: M | H19: RA 1080 Civil Engineer | I19: Contract of Service | J19: 2 | K19: 42308 | L19: 43465 | M19: y | N19: =CONCATENATE(DATEDIF(K19,L19,"Y"),"y ",DATEDIF(K19+(360*(DATEDIF(K19,L19,"Y"))),L19,"M"),"m ",DATEDIF(K19+(30.5*(DATEDIF(K19,L19,"M"))),L19,"D"),"d") -> #NUM! | O19: Ifugao | P19: Technical Services | Q19: Engineer III | R19: LFP | S19: 36409 | T19: JO020
A20: =A19+1 -> 13 | B20: Dalay-on | C20: Ivan Ley | D20: T | E20: 32955 | F20: =DATEDIF(E20,TODAY(),"Y") -> 36 | G20: M | H20: RA 1080 Civil Engineer | I20: Contract of Service | J20: 2 | K20: 42813 | L20: 43465 | M20: y | N20: =CONCATENATE(DATEDIF(K20,L20,"Y"),"y ",DATEDIF(K20+(360*(DATEDIF(K20,L20,"Y"))),L20,"M"),"m ",DATEDIF(K20+(30.5*(DATEDIF(K20,L20,"M"))),L20,"D"),"d") -> 1y 9m 12d | O20: Region | P20: Technical Services | Q20: Engineer II | R20: LFP | S20: 28417 | T20: JO039
A21: =A120+1 -> 15 | B21: Dangeo | C21: Delfin | D21: G | E21: 30375 | F21: =DATEDIF(E21,TODAY(),"Y") -> 43 | G21: M | H21: None | I21: Contract of Service | J21: 1 | K21: 42684 | L21: 43465 | M21: y | N21: =CONCATENATE(DATEDIF(K21,L21,"Y"),"y ",DATEDIF(K21+(360*(DATEDIF(K21,L21,"Y"))),L21,"M"),"m ",DATEDIF(K21+(30.5*(DATEDIF(K21,L21,"M"))),L21,"D"),"d") -> 2y 2m 19d | O21: Region | P21: Admin. Support Services | Q21: Driver | R21: Regular Funds | S21: 10833 | T21: JO032
A22: =A21+1 -> 16 | B22: Embargo | C22: Kennedy | D22: B | E22: 24088 | F22: =DATEDIF(E22,TODAY(),"Y") -> 60 | G22: M | H22: None | I22: Contract of Service | J22: 1 | K22: 42186 | L22: 43465 | M22: y | N22: =CONCATENATE(DATEDIF(K22,L22,"Y"),"y ",DATEDIF(K22+(360*(DATEDIF(K22,L22,"Y"))),L22,"M"),"m ",DATEDIF(K22+(30.5*(DATEDIF(K22,L22,"M"))),L22,"D"),"d") -> 3y 6m 29d | O22: Kalinga | P22: Security Services | Q22: Watchman | R22: Regular Funds | S22: 9478 | T22: JO014
A23: =A22+1 -> 17 | B23: Francia | C23: Judith | D23: C | E23: 24617 | F23: =DATEDIF(E23,TODAY(),"Y") -> 58 | G23: F | H23: None | I23: Contract of Service | J23: 1 | K23: 40483 | L23: 43465 | M23: y | N23: =CONCATENATE(DATEDIF(K23,L23,"Y"),"y ",DATEDIF(K23+(360*(DATEDIF(K23,L23,"Y"))),L23,"M"),"m ",DATEDIF(K23+(30.5*(DATEDIF(K23,L23,"M"))),L23,"D"),"d") -> 8y 3m 24d | O23: Region | P23: Janitorial Services | Q23: Cottage Caretaker | R23: Regular Funds | S23: 9478 | T23: JO010
A24: =A23+1 -> 18 | B24: Garnace | C24: Baldo | D24: N | F24: =DATEDIF(E24,TODAY(),"Y") -> 126 | G24: M | H24: None | I24: Contract of Service | J24: 2 | K24: 42922 | L24: 43465 | M24: y | N24: =CONCATENATE(DATEDIF(K24,L24,"Y"),"y ",DATEDIF(K24+(360*(DATEDIF(K24,L24,"Y"))),L24,"M"),"m ",DATEDIF(K24+(30*(DATEDIF(K24,L24,"M"))),L24,"D"),"d") -> 1y 5m 33d | O24: Region | P24: ADM Technical Support | Q24: RPMT PDO | R24: BUB/ADM | S24: 39151 | T24: JO050
A25: =A24+1 -> 19 | B25: Gatawa | C25: Jovany | D25: D | E25: 34105 | F25: =DATEDIF(E25,TODAY(),"Y") -> 32 | G25: M | H25: RA 1080 Civil Engineer | I25: Contract of Service | J25: 2 | K25: 42857 | L25: 43465 | M25: y | N25: =CONCATENATE(DATEDIF(K25,L25,"Y"),"y ",DATEDIF(K25+(360*(DATEDIF(K25,L25,"Y"))),L25,"M"),"m ",DATEDIF(K25+(30.5*(DATEDIF(K25,L25,"M"))),L25,"D"),"d") -> 1y 8m 29d | O25: Region | P25: Technical Services | Q25: Engineer II | R25: LFP | S25: 28417 | T25: JO041
A26: =A25+1 -> 20 | B26: Gernale | C26: Joe Pablo | D26: M | E26: 34289 | F26: =DATEDIF(E26,TODAY(),"Y") -> 32 | G26: M | H26: Professional | I26: Contract of Service | J26: 1 | K26: 42537 | L26: 43465 | M26: y | N26: =CONCATENATE(DATEDIF(K26,L26,"Y"),"y ",DATEDIF(K26+(360*(DATEDIF(K26,L26,"Y"))),L26,"M"),"m ",DATEDIF(K26+(30*(DATEDIF(K26,L26,"M"))),L26,"D"),"d") -> 2y 6m 28d | O26: Region | P26: Clerical Services | Q26: Clerk | R26: Regular Funds | S26: 11658 | T26: JO023
A27: =A26+1 -> 21 | B27: Haboc | C27: Felimon | D27: L | E27: 24168 | F27: =DATEDIF(E27,TODAY(),"Y") -> 60 | G27: M | H27: None | I27: Contract of Service | J27: 1 | K27: 42598 | L27: 43465 | M27: y | N27: =CONCATENATE(DATEDIF(K27,L27,"Y"),"y ",DATEDIF(K27+(360*(DATEDIF(K27,L27,"Y"))),L27,"M"),"m ",DATEDIF(K27+(30*(DATEDIF(K27,L27,"M"))),L27,"D"),"d") -> 2y 4m 27d | O27: Kalinga | P27: Admin. Support Services | Q27: Driver | R27: Regular Funds | S27: 10833 | T27: JO027
A28: =A27+1 -> 22 | B28: Khayad | C28: Ivy Rose | D28: A | E28: 32227 | F28: =DATEDIF(E28,TODAY(),"Y") -> 37 | G28: F | H28: RA 1080 Civil Engineer | I28: Contract of Service | J28: 2 | K28: 42186 | L28: 43465 | M28: y | N28: =CONCATENATE(DATEDIF(K28,L28,"Y"),"y ",DATEDIF(K28+(360*(DATEDIF(K28,L28,"Y"))),L28,"M"),"m ",DATEDIF(K28+(30.5*(DATEDIF(K28,L28,"M"))),L28,"D"),"d") -> 3y 6m 29d | O28: Mt. Province | P28: Technical Services | Q28: Engineer III | R28: LFP | S28: 36409 | T28: JO015
A29: =A28+1 -> 23 | B29: Kibod | C29: Diego | D29: F | E29: 27484 | F29: =DATEDIF(E29,TODAY(),"Y") -> 50 | G29: M | H29: None | I29: Contract of Service | J29: 1 | K29: 42339 | L29: 43465 | M29: y | N29: =CONCATENATE(DATEDIF(K29,L29,"Y"),"y ",DATEDIF(K29+(360*(DATEDIF(K29,L29,"Y"))),L29,"M"),"m ",DATEDIF(K29+(30.5*(DATEDIF(K29,L29,"M"))),L29,"D"),"d") -> 3y 1m 28d | O29: Benguet | P29: Admin. Support Services | Q29: Driver | R29: Regular Funds | S29: 10833 | T29: JO022
A30: =A29+1 -> 24 | B30: Lagazo | C30: Annabelle | E30: 29448 | F30: =DATEDIF(E30,TODAY(),"Y") -> 45 | G30: F | H30: RA 1080 Sanitary Engineer | I30: Contract of Service | J30: 2 | K30: 42818 | L30: 43465 | M30: y | N30: =CONCATENATE(DATEDIF(K30,L30,"Y"),"y ",DATEDIF(K30+(360*(DATEDIF(K30,L30,"Y"))),L30,"M"),"m ",DATEDIF(K30+(30.5*(DATEDIF(K30,L30,"M"))),L30,"D"),"d") -> 1y 9m 7d | O30: Region | P30: Technical Services | Q30: Engineer II | R30: Regular Funds | S30: 28417 | T30: JO040
A31: =A30+1 -> 25 | B31: Lawagan | C31: Wilner | D31: C | E31: 32575 | F31: =DATEDIF(E31,TODAY(),"Y") -> 37 | G31: M | H31: None | I31: Contract of Service | J31: 1 | K31: 42614 | L31: 43465 | M31: y | N31: =CONCATENATE(DATEDIF(K31,L31,"Y"),"y ",DATEDIF(K31+(360*(DATEDIF(K31,L31,"Y"))),L31,"M"),"m ",DATEDIF(K31+(30.5*(DATEDIF(K31,L31,"M"))),L31,"D"),"d") -> 2y 4m 28d | O31: Mt. Province | P31: Admin. Support Services | Q31: Driver | R31: Regular Funds | S31: 10833 | T31: JO029
A32: =A31+1 -> 26 | B32: Macli-ing | C32: Giezzel | D32: D | E32: 35092 | F32: =DATEDIF(E32,TODAY(),"Y") -> 30 | G32: F | H32: Professional | I32: Contract of Service | J32: 1 | K32: 42676 | L32: 43465 | M32: y | N32: =CONCATENATE(DATEDIF(K32,L32,"Y"),"y ",DATEDIF(K32+(360*(DATEDIF(K32,L32,"Y"))),L32,"M"),"m ",DATEDIF(K32+(30.5*(DATEDIF(K32,L32,"M"))),L32,"D"),"d") -> 2y 2m 27d | O32: Region | P32: Clerical Services | Q32: Clerk | R32: Regular Funds | S32: 11658 | T32: JO031
A33: =A32+1 -> 27 | B33: Miclat | C33: Reymarson | D33: P | E33: 32247 | F33: =DATEDIF(E33,TODAY(),"Y") -> 37 | G33: M | H33: None | I33: Contract of Service | J33: 2 | K33: 42871 | L33: 43465 | M33: y | N33: =CONCATENATE(DATEDIF(K33,L33,"Y"),"y ",DATEDIF(K33+(360*(DATEDIF(K33,L33,"Y"))),L33,"M"),"m ",DATEDIF(K33+(30.5*(DATEDIF(K33,L33,"M"))),L33,"D"),"d") -> 1y 7m 15d | O33: Benguet | P33: Assistance to Municipalities | Q33: CDO II | R33: BUB/ADM | S33: 28417 | T33: JO045
A34: =A33+1 -> 28 | B34: Moyaen | C34: Ariel | D34: P | E34: 28353 | F34: =DATEDIF(E34,TODAY(),"Y") -> 48 | G34: M | H34: RA 1080 Civil Engineer | I34: Contract of Service | J34: 2 | K34: 41325 | L34: 43465 | M34: y | N34: =CONCATENATE(DATEDIF(K34,L34,"Y"),"y ",DATEDIF(K34+(360*(DATEDIF(K34,L34,"Y"))),L34,"M"),"m ",DATEDIF(K34+(30.5*(DATEDIF(K34,L34,"M"))),L34,"D"),"d") -> 5y 11m 5d | O34: Region | P34: Technical Services | Q34: Engineer III | R34: LFP | S34: 36409 | T34: JO011
A35: =A34+1 -> 29 | B35: Moyaen | C35: Carmen | D35: G | E35: 30513 | F35: =DATEDIF(E35,TODAY(),"Y") -> 42 | G35: F | H35: Social Worker | I35: Contract of Service | J35: 2 | K35: 42922 | L35: 43465 | M35: y | N35: =CONCATENATE(DATEDIF(K35,L35,"Y"),"y ",DATEDIF(K35+(360*(DATEDIF(K35,L35,"Y"))),L35,"M"),"m ",DATEDIF(K35+(30*(DATEDIF(K35,L35,"M"))),L35,"D"),"d") -> 1y 5m 33d | O35: Region | P35: ADM Technical Support | Q35: RPMT Team Leader | R35: BUB/ADM | S35: 39151 | T35: JO049
A36: =A35+1 -> 30 | B36: Octaviano | C36: Julie Rose | D36: A | E36: 32633 | F36: =DATEDIF(E36,TODAY(),"Y") -> 36 | G36: F | H36: RA 1080 CPA | I36: Contract of Service | J36: 2 | K36: 42857 | L36: 43465 | M36: y | N36: =CONCATENATE(DATEDIF(K36,L36,"Y"),"y ",DATEDIF(K36+(360*(DATEDIF(K36,L36,"Y"))),L36,"M"),"m ",DATEDIF(K36+(30.5*(DATEDIF(K36,L36,"M"))),L36,"D"),"d") -> 1y 8m 29d | O36: Region | P36: Admin. Support Services | Q36: Financial Analyst | R36: LFP | S36: 36409 | T36: JO034
A37: =A121+1 -> 32 | B37: Samson | C37: Aljon Paulus | D37: M | E37: 32748 | F37: =DATEDIF(E37,TODAY(),"Y") -> 36 | G37: M | H37: None | I37: Contract of Service | J37: 2 | K37: 42857 | L37: 43465 | M37: y | N37: =CONCATENATE(DATEDIF(K37,L37,"Y"),"y ",DATEDIF(K37+(360*(DATEDIF(K37,L37,"Y"))),L37,"M"),"m ",DATEDIF(K37+(30.5*(DATEDIF(K37,L37,"M"))),L37,"D"),"d") -> 1y 8m 29d | O37: Region | P37: Operations Support Services | Q37: DB Administrator | R37: ISTMS | S37: 30000 | T37: JO043
A38: =A37+1 -> 33 | B38: Siador | C38: Arlyn | D38: C | E38: 29664 | F38: =DATEDIF(E38,TODAY(),"Y") -> 45 | G38: F | H38: Sub-Professional | I38: Contract of Service | J38: 1 | K38: 42537 | L38: 43465 | M38: y | N38: =CONCATENATE(DATEDIF(K38,L38,"Y"),"y ",DATEDIF(K38+(360*(DATEDIF(K38,L38,"Y"))),L38,"M"),"m ",DATEDIF(K38+(30*(DATEDIF(K38,L38,"M"))),L38,"D"),"d") -> 2y 6m 28d | O38: Region | P38: Clerical Services | Q38: Clerk | R38: Regular Funds | S38: 11658 | T38: JO024
A39: =A38+1 -> 34 | B39: Taclawan | C39: Clifford | D39: B | E39: 26497 | F39: =DATEDIF(E39,TODAY(),"Y") -> 53 | G39: M | H39: None | I39: Contract of Service | J39: 1 | K39: 42186 | L39: 43465 | M39: y | N39: =CONCATENATE(DATEDIF(K39,L39,"Y"),"y ",DATEDIF(K39+(360*(DATEDIF(K39,L39,"Y"))),L39,"M"),"m ",DATEDIF(K39+(30.5*(DATEDIF(K39,L39,"M"))),L39,"D"),"d") -> 3y 6m 29d | O39: Kalinga | P39: Security Services | Q39: Watchman | R39: Regular Funds | S39: 9478 | T39: JO016
A40: =A39+1 -> 35 | B40: Talusig | C40: Trinidad | D40: C | E40: 25123 | F40: =DATEDIF(E40,TODAY(),"Y") -> 57 | G40: F | H40: None | I40: Contract of Service | J40: 1 | K40: 41372 | L40: 43465 | M40: y | N40: =CONCATENATE(DATEDIF(K40,L40,"Y"),"y ",DATEDIF(K40+(360*(DATEDIF(K40,L40,"Y"))),L40,"M"),"m ",DATEDIF(K40+(30*(DATEDIF(K40,L40,"M"))),L40,"D"),"d") -> 5y 9m 53d | O40: Region | P40: Janitorial Services | Q40: Utility/Janitor | R40: Regular Funds | S40: 9478 | T40: JO012
A41: =A40+1 -> 36 | B41: Tekwaban | C41: Patrick | D41: B | E41: 32206 | F41: =DATEDIF(E41,TODAY(),"Y") -> 38 | G41: M | H41: RA 1080 Civil Engineer | I41: Contract of Service | J41: 2 | K41: 42310 | L41: 43465 | M41: y | N41: =CONCATENATE(DATEDIF(K41,L41,"Y"),"y ",DATEDIF(K41+(360*(DATEDIF(K41,L41,"Y"))),L41,"M"),"m ",DATEDIF(K41+(30*(DATEDIF(K41,L41,"M"))),L41,"D"),"d") -> 3y 2m 45d | O41: Benguet | P41: Technical Services | Q41: Engineer III | R41: LFP | S41: 36409 | T41: JO021
A42: =A41+1 -> 37 | B42: Villaflor | C42: Nino Boyet | D42: F | E42: 34046 | F42: =DATEDIF(E42,TODAY(),"Y") -> 33 | G42: M | H42: None | I42: Contract of Service | J42: 1 | K42: 42758 | L42: 43465 | M42: y | N42: =CONCATENATE(DATEDIF(K42,L42,"Y"),"y ",DATEDIF(K42+(360*(DATEDIF(K42,L42,"Y"))),L42,"M"),"m ",DATEDIF(K42+(30*(DATEDIF(K42,L42,"M"))),L42,"D"),"d") -> 1y 11m 17d | O42: Apayao | P42: Security Services | Q42: Watchman | R42: Regular Funds | S42: 9478 | T42: JO036
...

Sheet staffing plan
A1: PERSONAL SERVICES ITEMIZATION AND PLANTILLA OF PERSONNEL
A2: =CONCATENATE("As of ",TEXT(NOW(),"mmmm dd, yyyy")) -> As of March 24, 2026
A4: DEPARTMENT OF THE INTERIOR AND LOCAL GOVERNMENT
A5: Cordillera Administrative Region
B7: POSITION TITLE | C7: S G | AH7: A N N U A L S A L A R Y | AJ7: STEP | AK7: A R E A | AW7: I N C U M B E N T | AY7: SEX | AZ7: DATE OF BIRTH | BF7: Tax Identification Number (TIN) | BG7: DATE OF ORIGINAL APPT | BK7: DATE OF LAST PROMO-TION | BM7: STATUS | BN7: ELIGIBILITY | BP7: REMARK
A8: ITEM NUMBER | D8: QUALIFICATION STANDARD | I8: Shrt Position Title | J8: PTStation | K8: PosStSex | L8: Gender Station | M8: Competencies Required | AH8: AUTHORIZED | AI8: ACTUAL | AK8: CODE | AL8: TYPE | AM8: LEVEL | AN8: P/P/A/ ATTRI-BUTION | AO8: Station Allocation | AP8: Specific Allocation | AQ8: 1998 & 2010 RP plantila location per code | AR8: LAST NAME | AS8: FIRST NAME | AT8: MIDDLE NAME | AU8: MI | AX8: STATION | BA8: age | BB8: age group | BC8: Age group station | BD8: genderagegroupstation | BE8: PTSexCat | BH8: date of tranfer to DILG | BI8: age in service | BJ8: YRS IN DILG | BL8: YRS IN THE POSI | BO8: Highest Educ attainment | BQ8: Status grade
A9: (1) | B9: (2) | D9: Educ | E9: Exp | F9: Trng | G9: Eligibility | H9: Duties and Responsibilities | M9: Core | Q9: functional (LGOOs) | X9: Non-LGOOs | AD9: Leadership | AH9: (3) | AI9: (4) | AJ9: (5) | AK9: (6) | AL9: (7) | AM9: (8) | AN9: (9) | AW9: 10 | AY9: 11 | AZ9: 12 | BF9: 13 | BG9: 14 | BK9: 15 | BM9: 16 | BN9: 17 | BP9: 18
M10: CESGG | N10: CF | O10: EER | P10: OS | Q10: EC | R10: I | S10: MKI | T10: PRA | U10: PDM | V10: RB | W10: TP | X10: C/AT | Y10: C/WO | Z10: PO | AA10: I/D/RM | AB10: EC | AC10: AS | AD10: DIO | AE10: PWMT | AF10: PSDM | AG10: OA
A11: 61,000 Office of the Regional Director
A12: OSEC-DILGB-DIR4-18-1998 | B12: Director IV | C12: 28 | D12: Bachelors Degree | E12: 3 years of supervisory experience | F12: none required | G12: Civil Service Executive Eligibility (CSEE)/ Career Executive Service (CES) | I12: DIR4 | J12: =IF(AX12="Regional Office",CONCATENATE(I12,"R"),IF(AX12="Abra",CONCATENATE(I12,"Ab"),IF(AX12="Apayao",CONCATENATE(I12,"Ap"),IF(AX12="Baguio City",CONCATENATE(I12,"BC"),IF(AX12="Ifugao",CONCATENATE(I12,"I"),IF(AX12="Mt. Province",CONCATENATE(I12,"MP"),IF(AX12="Kalinga",CONCATENATE(I12,"K"),IF(AX12="Benguet",CONCATENATE(I12,"B"),"Vacant")))))))) -> DIR4R | K12: =CONCATENATE(J12,AY12) -> DIR4RM | L12: =IF(AX12="Regional Office",(IF(AY12="M","RM","RF")),IF(AX12="Abra",(IF(AY12="M","AbM","AbF")),IF(AX12="Baguio City",(IF(AY12="M","BCM","BCF")),IF(AX12="Apayao",(IF(AY12="M","ApM","ApF")),IF(AX12="Benguet",(IF(AY12="M","BM","BF")),IF(AX12="Ifugao",(IF(AY12="M","IM","IF")),IF(AX12="Kalinga",(IF(AY12="M","KM","KF")),IF(AX12="Mt. Province",(IF(AY12="M","MPM","MPF")),"XXX")))))))) -> RM | M12: 4 | N12: 4 | O12: 4 | P12: 4 | AH12: =VLOOKUP(C12,idica,2,FALSE)*12 -> 1646340 | AI12: =(SUMPRODUCT((norman=C12)*(grace=AJ12)*(barnachea)))*12 -> 1673208 | AJ12: 2 | AK12: 011 | AL12: R | AM12: K | AN12: 310100100001000 | AO12: Regional Office | AP12: ORD | AQ12: Regional Office | AR12: IRINGAN | AS12: Marlo | AT12: Lingan | AU12: =LEFT(AT12)&IF(ISNUMBER(FIND(" ",AT12)),MID(AT12,FIND(" ",AT12)+1,1),"")&IF(ISNUMBER(FIND(" ",AT12,FIND(" ",AT12)+1)),MID(AT12,FIND(" ",AT12,FIND(" ",AT12)+1)+1,1),"") -> L | AV12: =PROPER(CONCATENATE(AS12," ",AU12,". ",AR12)) -> Marlo L. Iringan | AW12: =CONCATENATE(AR12,", ",AS12," ",AT12) -> IRINGAN, Marlo Lingan | AX12: Regional Office | AY12: M | AZ12: 24422 | BA12: =DATEDIF(AZ12,TODAY(),"Y") -> 59 | BB12: =IF(BA12<30,"A",IF(BA12<40,"B",IF(BA12<50,"C",IF(BA12<60,"D",IF(BA12<65,"E","VACANT"))))) -> D | BC12: =+IF(AX12="Regional Office",(IF(BB12="A","RA",(IF(BB12="B","RB",IF(BB12="C","RC",IF(BB12="D","RD",IF(BB12="E","RE","VACANT"))))))),IF(AX12="Abra",(IF(BB12="A","AbA",(IF(BB12="B","AbB",IF(BB12="C","AbC",IF(BB12="D","AbD",IF(BB12="E","AbE","VACANT"))))))),IF(AX12="Baguio City",(IF(BB12="A","BCA",(IF(BB12="B","BCB",IF(BB12="C","BCC",IF(BB12="D","BCD",IF(BB12="E","BCE","VACANT"))))))),IF(AX12="Apayao",(IF(BB12="A","ApA",(IF(BB12="B","ApB",IF(BB12="C","ApC",IF(BB12="D","ApD",IF(BB12="E","ApE","VACANT"))))))),IF(AX12="Benguet",(IF(BB12="A","BA",(IF(BB12="B","BB",IF(BB12="C","BC",IF(BB12="D","BD",IF(BB12="E","BE","VACANT"))))))),IF(AX12="Ifugao",(IF(BB12="A","IA",(IF(BB12="B","IB",IF(BB12="C","IC",IF(BB12="D","ID",IF(BB12="E","IE","VACANT"))))))),IF(AX12="Kalinga",(IF(BB12="A","KA",(IF(BB12="B","KB",IF(BB12="C","KC",IF(BB12="D","KD",IF(BB12="E","KE","VACANT"))))))),IF(AX12="Mt. Province",(IF(BB12="A","MPA",(IF(BB12="B","MPB",IF(BB12="C","MPC",IF(BB12="D","MPD",IF(BB12="E","MPE","VACANT"))))))),"XXX")))))))) -> RD | BD12: =CONCATENATE(BC12,AY12) -> RDM | BE12: =CONCATENATE(I12,BD12) -> DIR4RDM | BF12: 133-289-742 | BG12: 32546 | BH12: 32675 | BI12: =DATEDIF(BG12,TODAY(),"Y") -> 37 | BJ12: =DATEDIF(BH12,TODAY(),"Y") -> 36 | BK12: 43146 | BL12: =DATEDIF(BK12,TODAY(),"Y") -> 8 | BM12: P | BN12: CESO III | BO12: MPA - 35u | BQ12: =CONCATENATE(3,AY12,BM12) -> 3MP
A13: OSEC-DILGB-DIR3-4-1998 | B13: Director III | C13: 27 | D13: Bachelors Degree | E13: 3 years of supervisory experience | F13: none required | G13: Civil Service Executive Eligibility (CSEE)/ Career Executive Service (CES) | I13: DIR3 | J13: =IF(AX13="Regional Office",CONCATENATE(I13,"R"),IF(AX13="Abra",CONCATENATE(I13,"Ab"),IF(AX13="Apayao",CONCATENATE(I13,"Ap"),IF(AX13="Baguio City",CONCATENATE(I13,"BC"),IF(AX13="Ifugao",CONCATENATE(I13,"I"),IF(AX13="Mt. Province",CONCATENATE(I13,"MP"),IF(AX13="Kalinga",CONCATENATE(I13,"K"),IF(AX13="Benguet",CONCATENATE(I13,"B"),"Vacant")))))))) -> DIR3R | K13: =CONCATENATE(J13,AY13) -> DIR3RF | L13: =IF(AX13="Regional Office",(IF(AY13="M","RM","RF")),IF(AX13="Abra",(IF(AY13="M","AbM","AbF")),IF(AX13="Baguio City",(IF(AY13="M","BCM","BCF")),IF(AX13="Apayao",(IF(AY13="M","ApM","ApF")),IF(AX13="Benguet",(IF(AY13="M","BM","BF")),IF(AX13="Ifugao",(IF(AY13="M","IM","IF")),IF(AX13="Kalinga",(IF(AY13="M","KM","KF")),IF(AX13="Mt. Province",(IF(AY13="M","MPM","MPF")),"XXX")))))))) -> RF | M13: 4 | N13: 4 | O13: 4 | P13: 4 | AH13: =VLOOKUP(C13,idica,2,FALSE)*12 -> 1456932 | AI13: =(SUMPRODUCT((norman=C13)*(grace=AJ13)*(barnachea)))*12 -> 1480716 | AJ13: 2 | AK13: 011 | AL13: R | AM13: K | AN13: 310100100001000 | AO13: Regional Office | AP13: ORD | AQ13: Regional Office | AR13: SAN JOSE | AS13: Araceli | AT13: Arruejo | AU13: =LEFT(AT13)&IF(ISNUMBER(FIND(" ",AT13)),MID(AT13,FIND(" ",AT13)+1,1),"")&IF(ISNUMBER(FIND(" ",AT13,FIND(" ",AT13)+1)),MID(AT13,FIND(" ",AT13,FIND(" ",AT13)+1)+1,1),"") -> A | AV13: =PROPER(CONCATENATE(AS13," ",AU13,". ",AR13)) -> Araceli A. San Jose | AW13: =CONCATENATE(AR13,", ",AS13," ",AT13) -> SAN JOSE, Araceli Arruejo | AX13: Regional Office | AY13: F | AZ13: 25461 | BA13: =DATEDIF(AZ13,TODAY(),"Y") -> 56 | BB13: =IF(BA13<30,"A",IF(BA13<40,"B",IF(BA13<50,"C",IF(BA13<60,"D",IF(BA13<65,"E","VACANT"))))) -> D | BC13: =+IF(AX13="Regional Office",(IF(BB13="A","RA",(IF(BB13="B","RB",IF(BB13="C","RC",IF(BB13="D","RD",IF(BB13="E","RE","VACANT"))))))),IF(AX13="Abra",(IF(BB13="A","AbA",(IF(BB13="B","AbB",IF(BB13="C","AbC",IF(BB13="D","AbD",IF(BB13="E","AbE","VACANT"))))))),IF(AX13="Baguio City",(IF(BB13="A","BCA",(IF(BB13="B","BCB",IF(BB13="C","BCC",IF(BB13="D","BCD",IF(BB13="E","BCE","VACANT"))))))),IF(AX13="Apayao",(IF(BB13="A","ApA",(IF(BB13="B","ApB",IF(BB13="C","ApC",IF(BB13="D","ApD",IF(BB13="E","ApE","VACANT"))))))),IF(AX13="Benguet",(IF(BB13="A","BA",(IF(BB13="B","BB",IF(BB13="C","BC",IF(BB13="D","BD",IF(BB13="E","BE","VACANT"))))))),IF(AX13="Ifugao",(IF(BB13="A","IA",(IF(BB13="B","IB",IF(BB13="C","IC",IF(BB13="D","ID",IF(BB13="E","IE","VACANT"))))))),IF(AX13="Kalinga",(IF(BB13="A","KA",(IF(BB13="B","KB",IF(BB13="C","KC",IF(BB13="D","KD",IF(BB13="E","KE","VACANT"))))))),IF(AX13="Mt. Province",(IF(BB13="A","MPA",(IF(BB13="B","MPB",IF(BB13="C","MPC",IF(BB13="D","MPD",IF(BB13="E","MPE","VACANT"))))))),"XXX")))))))) -> RD | BD13: =CONCATENATE(BC13,AY13) -> RDF | BE13: =CONCATENATE(I13,BD13) -> DIR3RDF | BF13: 187-269-180 | BG13: 35457 | BH13: 35457 | BI13: =DATEDIF(BG13,TODAY(),"Y") -> 29 | BJ13: =DATEDIF(BH13,TODAY(),"Y") -> 29 | BK13: 43549 | BL13: =DATEDIF(BK13,TODAY(),"Y") -> 6 | BM13: P | BN13: CESO IV | BO13: MPA | BQ13: =CONCATENATE(3,AY13,BM13) -> 3FP
A14: OSEC-DILGB-ATTY4-9-1998 | B14: Attorney IV | C14: 23 | D14: Bachelor of Laws | E14: 2 years of relevant experience | F14: 8 hours of relevant training | G14: RA 1080 | H14: 1. Under the general supervision of the Regional Diretor, prepares letters/correspondence and takes appropriate actions on legal matters brought to the office by local government officials, DILG Central Office, other national agencies, and other persons/entities; 2. Renders written legal opinions or comments on queries endorsed to the regional office by the Central Office, field offices, including local governement units, and other entities; 3. Acts as a Resource Person and renders on-site technical assistance/advice to DILG field personnel, LGU officials and functionaries and to the geberal public on legal and operational matters, upon the directive of the Regional Director; 4. Acts as the Legal Adviser of the Regional Director and assists the Regional Director in implementing the decisions/reso;utions of the Ombudsman, Courts, and other quasi-juducial bodies; 5. Conducts confidential/discreet fact-finding inquiries and investigations as directed by the Office of the President, DILG Central Office, the Regional Director, Civil Service Commission, and the Ombudsman; 6. Conducts fact-finding inquiry/investigations relating to cases of DILG Regional Office personnel and recommends actions on cases filed against DILG personnel; 7. Conducts continuing researches and studies on laws, rules and regulations affecting local government units and Office operations; 8. Reviews drafts of proposed circulars, guidelines and/or issuances pertaining to DILG and local government operations, as well as review of drafts of contracts/MOA/MOU between DILG and its contracting parties; and 9. Prepare reports, communications and all other issunaces required by management. | I14: ATTY4 | J14: =IF(AX14="Regional Office",CONCATENATE(I14,"R"),IF(AX14="Abra",CONCATENATE(I14,"Ab"),IF(AX14="Apayao",CONCATENATE(I14,"Ap"),IF(AX14="Baguio City",CONCATENATE(I14,"BC"),IF(AX14="Ifugao",CONCATENATE(I14,"I"),IF(AX14="Mt. Province",CONCATENATE(I14,"MP"),IF(AX14="Kalinga",CONCATENATE(I14,"K"),IF(AX14="Benguet",CONCATENATE(I14,"B"),"Vacant")))))))) -> ATTY4R | K14: =CONCATENATE(J14,AY14) -> ATTY4RF | L14: =IF(AX14="Regional Office",(IF(AY14="M","RM","RF")),IF(AX14="Abra",(IF(AY14="M","AbM","AbF")),IF(AX14="Baguio City",(IF(AY14="M","BCM","BCF")),IF(AX14="Apayao",(IF(AY14="M","ApM","ApF")),IF(AX14="Benguet",(IF(AY14="M","BM","BF")),IF(AX14="Ifugao",(IF(AY14="M","IM","IF")),IF(AX14="Kalinga",(IF(AY14="M","KM","KF")),IF(AX14="Mt. Province",(IF(AY14="M","MPM","MPF")),"XXX")))))))) -> RF | M14: 3 | N14: 3 | O14: 3 | P14: 3 | AH14: =VLOOKUP(C14,idica,2,FALSE)*12 -> 885732 | AI14: =(SUMPRODUCT((norman=C14)*(grace=AJ14)*(barnachea)))*12 -> 885732 | AJ14: 1 | AK14: 011 | AL14: R | AM14: S | AN14: 310100100001000 | AO14: Regional Office | AP14: ORD | AQ14: Regional Office | AR14: SHONTOGAN | AS14: Genevieve | AT14: Miguel | AU14: =LEFT(AT14)&IF(ISNUMBER(FIND(" ",AT14)),MID(AT14,FIND(" ",AT14)+1,1),"")&IF(ISNUMBER(FIND(" ",AT14,FIND(" ",AT14)+1)),MID(AT14,FIND(" ",AT14,FIND(" ",AT14)+1)+1,1),"") -> M | AV14: =PROPER(CONCATENATE(AS14," ",AU14,". ",AR14)) -> Genevieve M. Shontogan | AW14: =CONCATENATE(AR14,", ",AS14," ",AT14) -> SHONTOGAN, Genevieve Miguel | AX14: Regional Office | AY14: F | AZ14: 31267 | BA14: =DATEDIF(AZ14,TODAY(),"Y") -> 40 | BB14: =IF(BA14<30,"A",IF(BA14<40,"B",IF(BA14<50,"C",IF(BA14<60,"D",IF(BA14<65,"E","VACANT"))))) -> C | BC14: =+IF(AX14="Regional Office",(IF(BB14="A","RA",(IF(BB14="B","RB",IF(BB14="C","RC",IF(BB14="D","RD",IF(BB14="E","RE","VACANT"))))))),IF(AX14="Abra",(IF(BB14="A","AbA",(IF(BB14="B","AbB",IF(BB14="C","AbC",IF(BB14="D","AbD",IF(BB14="E","AbE","VACANT"))))))),IF(AX14="Baguio City",(IF(BB14="A","BCA",(IF(BB14="B","BCB",IF(BB14="C","BCC",IF(BB14="D","BCD",IF(BB14="E","BCE","VACANT"))))))),IF(AX14="Apayao",(IF(BB14="A","ApA",(IF(BB14="B","ApB",IF(BB14="C","ApC",IF(BB14="D","ApD",IF(BB14="E","ApE","VACANT"))))))),IF(AX14="Benguet",(IF(BB14="A","BA",(IF(BB14="B","BB",IF(BB14="C","BC",IF(BB14="D","BD",IF(BB14="E","BE","VACANT"))))))),IF(AX14="Ifugao",(IF(BB14="A","IA",(IF(BB14="B","IB",IF(BB14="C","IC",IF(BB14="D","ID",IF(BB14="E","IE","VACANT"))))))),IF(AX14="Kalinga",(IF(BB14="A","KA",(IF(BB14="B","KB",IF(BB14="C","KC",IF(BB14="D","KD",IF(BB14="E","KE","VACANT"))))))),IF(AX14="Mt. Province",(IF(BB14="A","MPA",(IF(BB14="B","MPB",IF(BB14="C","MPC",IF(BB14="D","MPD",IF(BB14="E","MPE","VACANT"))))))),"XXX")))))))) -> RC | BD14: =CONCATENATE(BC14,AY14) -> RCF | BE14: =CONCATENATE(I14,BD14) -> ATTY4RCF | BF14: 414-630-652 | BG14: 41824 | BH14: 43360 | BI14: =DATEDIF(BG14,TODAY(),"Y") -> 11 | BJ14: =DATEDIF(BH14,TODAY(),"Y") -> 7 | BK14: 43360 | BL14: =DATEDIF(BK14,TODAY(),"Y") -> 7 | BM14: P | BN14: RA 1080 | BO14: LLb | BQ14: =CONCATENATE(2,AY14,BM14) -> 2FP
